<?xml version='1.0'?>

<robot name="udacity_bot" xmlns:xacro="http://www.ros.org/wiki/xacro">

  <xacro:include filename="$(find udacity_bot)/urdf/udacity_bot.gazebo" />

  <link name="robot_footprint"></link>

  <joint name="robot_footprint_joint" type="fixed">
    <origin xyz="0 0 0" rpy="0 0 0" />
    <parent link="robot_footprint"/>
    <child link="chassis" />
  </joint>


  <link name='chassis'>
    <pose>0 0 0.1 0 0 0</pose>

    <inertial>
      <mass value="15.0"/>
      <origin xyz="0.0 0 0" rpy=" 0 0 0"/>
      <inertia
          ixx="0.1" ixy="0" ixz="0"
          iyy="0.1" iyz="0"
          izz="0.1"
      />
    </inertial>

    <collision name='collision'>
      <origin xyz="0 0 0" rpy=" 0 0 0"/>
      <geometry>
        <cylinder length="0.1" radius="0.15"/>
      </geometry>
    </collision>

    <visual name='chassis_visual'>
      <origin xyz="0 0 0" rpy=" 0 0 0"/>
      <geometry>
        <cylinder length="0.1" radius="0.15"/>
      </geometry>
    </visual>


    <collision name='back_caster_collision'>
      <origin xyz="-0.07 -0.07 -0.07" rpy=" 0 0 0"/>
      <geometry>
        <sphere radius="0.0299"/>
      </geometry>
    </collision>

    <visual name='back_caster_visual'>
      <origin xyz="-0.07 -0.07 -0.07" rpy=" 0 0 0"/>
      <geometry>
        <sphere radius="0.03"/>
      </geometry>
    </visual>

    <collision name='front_caster_collision'>
      <origin xyz="0.07 -0.07 -0.07" rpy=" 0 0 0"/>
      <geometry>
        <sphere radius="0.0299"/>
      </geometry>
    </collision>

    <visual name='front_caster_visual'>
      <origin xyz="0.07 -0.07 -0.07" rpy=" 0 0 0"/>
      <geometry>
        <sphere radius="0.03"/>
      </geometry>
    </visual>


    <collision name='right_caster_collision'>
      <origin xyz="-0.07 0.07 -0.07" rpy=" 0 0 0"/>
      <geometry>
        <sphere radius="0.0299"/>
      </geometry>
    </collision>

    <visual name='right_caster_visual'>
      <origin xyz="-0.07 0.07 -0.07" rpy=" 0 0 0"/>
      <geometry>
        <sphere radius="0.03"/>
      </geometry>
    </visual>


    <collision name='left_caster_collision'>
      <origin xyz="0.07 0.07 -0.07" rpy=" 0 0 0"/>a
      <geometry>
        <sphere radius="0.0299"/>
      </geometry>
    </collision>

    <visual name='left_caster_visual'>
      <origin xyz="0.07 0.07 -0.07" rpy=" 0 0 0"/>
      <geometry>
        <sphere radius="0.03"/>
      </geometry>
    </visual>

  </link>




  <link name='left_wheel'>
    <inertial>
      <mass value="5.0"/>
      <origin xyz="0.0 0 0" rpy=" 0 1.5707 1.5707"/>
      <inertia
          ixx="0.1" ixy="0" ixz="0"
          iyy="0.1" iyz="0"
          izz="0.1"
      />
    </inertial>

    <visual>
      <geometry>
        <cylinder length="0.05" radius="0.1"/>
      </geometry>
      <origin xyz="0 0 0" rpy="0 1.5707 1.5707"/>
    </visual>

    <collision>
      <geometry>
        <cylinder length="0.05" radius="0.1"/>
      </geometry>
      <origin xyz="0 0 0" rpy="0 1.5707 1.5707"/>
    </collision>
  </link>


  <link name='right_wheel'>
    <inertial>
      <mass value="5.0"/>
      <origin xyz="0.0 0 0" rpy=" 0 1.5707 1.5707"/>
      <inertia
          ixx="0.1" ixy="0" ixz="0"
          iyy="0.1" iyz="0"
          izz="0.1"
      />
    </inertial>

    <visual>
      <geometry>
        <cylinder length="0.05" radius="0.1"/>
      </geometry>
      <origin xyz="0 0 0" rpy="0 1.5707 1.5707"/>
    </visual>

    <collision>
      <geometry>
        <cylinder length="0.05" radius="0.1"/>
      </geometry>
      <origin xyz="0 0 0" rpy="0 1.5707 1.5707"/>
    </collision>
  </link>

  <joint type="continuous" name="left_wheel_hinge">
    <origin xyz="0 0.15 0" rpy="0 0 0"/>
    <child link="left_wheel"/>
    <parent link="chassis"/>
    <axis xyz="0 1 0" rpy="0 0 0"/>
    <limit effort="10000" velocity="1000"/>
    <dynamics damping="1.0" friction="1.0"/>
  </joint>


  <joint type="continuous" name="right_wheel_hinge">
    <origin xyz="0 -0.15 0" rpy="0 0 0"/>
    <child link="right_wheel"/>
    <parent link="chassis"/>
    <axis xyz="0 1 0" rpy="0 0 0"/>
    <limit effort="10000" velocity="1000"/>
    <dynamics damping="1.0" friction="1.0"/>
  </joint>




  <link name="camera">
    <inertial>
      <mass value="0.1"/>
      <origin xyz="0 0 0" rpy="0 0 0"/>
      <inertia
          ixx="1e-6" ixy="0" ixz="0"
          iyy="1e-6" iyz="0"
          izz="1e-6"
      />
    </inertial>
    <visual>
      <geometry>
        <box size="0.05 0.05 0.05"/>
      </geometry>
      <origin xyz="0 0 0" rpy="0 0 0"/>
    </visual>
    <collision>
      <geometry>
        <box size="0.05 0.05 0.05"/>
      </geometry>
      <origin xyz="0 0 0" rpy="0 0 0"/>
    </collision>
  </link>

  <joint type="fixed" name="camera_joint">
    <origin xyz="0.15 0 0" rpy="0 0 0"/>
    <child link="camera"/>
    <parent link="chassis"/>
  </joint>


    <link name="hokuyo">
    <inertial>
      <mass value="0.1"/>
      <origin xyz="0 0 0" rpy="0 0 0"/>
      <inertia
          ixx="1e-6" ixy="0" ixz="0"
          iyy="1e-6" iyz="0"
          izz="1e-6"
      />
    </inertial>

    <visual>
      <geometry>
        <mesh filename="package://udacity_bot/meshes/hokuyo.dae"/>
      </geometry>
      <origin xyz="0 0 0" rpy="0 0 0"/>
    </visual>

    <collision>
      <geometry>
        <box size="0.1 0.1 0.1"/>
      </geometry>
      <origin xyz="0 0 0" rpy="0 0 0"/>
    </collision>
  </link>

  <joint type="fixed" name="hokuyo_joint">
    <origin xyz="0.15 0 0.1" rpy="0 0 0"/>
    <child link="hokuyo"/>
    <parent link="chassis"/>
  </joint>

</robot>

